Workbook

Sheet EXAMPLE FORM
E2: MUST READ: How to use? 1. Only click a checkbox when the topic on the left - is 100% completed 2. Don't check the box if you "just" checked the topic if it was applicable 3. The same topic can be in multiple stages (different levels of maturity) | F2: FR | G2: NL | H2: DE | I2: UK | J2: Adaptation topics (V) | K2: Topics not finalized (X)
F3: TRUE | G3: TRUE | H3: TRUE | I3: TRUE | J3: =(COUNTIF(F:I,TRUE))-COUNTIF(F3:I3,true) -> 23 | K3: =COUNTIF(F:I,FALSE) -> 41
B4: =K59 -> 0.36197917 | F4: =COUNTIF(F:F,TRUE) -> 9 | G4: =COUNTIF(G:G,TRUE) -> 7 | H4: =COUNTIF(H:H,TRUE) -> 6 | I4: =COUNTIF(I:I,TRUE) -> 5
F6: =COUNTIF(F:F,FALSE) -> 8 | G6: =COUNTIF(G:G,FALSE) -> 10 | H6: =COUNTIF(H:H,FALSE) -> 11 | I6: =COUNTIF(I:I,FALSE) -> 12
C8: Maturity | D8: # | E8: Topics | F8: FR | G8: NL | H8: DE | I8: UK | J8: Details | K8: Next steps
E9: If a topic is not relevant for the client - delete the checkbox | F9: Only check a box if the topic is fully integrated | J9: Explain what the issue is if not checked | K9: What would be the next steps to finalize the topic
B10: 1
C11: Keywords | F11: =IFERROR(__xludf.DUMMYFUNCTION("SPARKLINE(COUNTIF(F13:I26,TRUE),{""charttype"",""bar"";""max"",COUNTA(F13:I26);""color1"",""green""})"),"") | K11: =COUNTIF(F13:I26,TRUE)/COUNTA(F13:I26) -> 0.35416667
B13: =COUNTIF(F13:I17,TRUE)/COUNTA(F13:I17) -> 0.45 | C13: Basic | D13: 1 | E13: Low amount of keywords; generic keywords without including searc intent | F13: TRUE | G13: TRUE | H13: TRUE | I13: TRUE | J13: All good
D14: 2 | E14: Account structure (based on Hagakure) | F14: TRUE | G14: TRUE | H14: FALSE | I14: FALSE | J14: No Hagakure in place for DE&UK | K14: Copy strategy of NL+FR to other markets
D15: 3 | E15: Keyword research | F15: TRUE | G15: FALSE | H15: FALSE | I15: FALSE | J15: Only french cope found | K15: Align with SEO and SEA regarding reports
D16: 4 | E16: Standard Namig Convention | F16: TRUE | G16: FALSE | H16: TRUE | I16: FALSE | J16: NL and UK are missing naming convention | K16: Look into a naming convention builder / or tooling which helps for reporting
D17: 5 | E17: Set-up base range of keywords | F17: FALSE | G17: FALSE | H17: FALSE | I17: FALSE | J17: Not in place yet
B18: =COUNTIF(F18:I19,TRUE)/COUNTA(F18:I19) -> 0.5 | C18: Advanced | D18: 6 | E18: Campaign segmentation based on customer journey | F18: FALSE | G18: FALSE | H18: FALSE | I18: FALSE | J18: Customer journey for every country seems different | K18: Write down customer journey for all markets
D19: 7 | E19: Negative keyword list | F19: TRUE | G19: TRUE | H19: TRUE | I19: TRUE | J19: All good
B20: =COUNTIF(F20:I23,TRUE)/COUNTA(F20:I23) -> 0.25 | C20: Expert | D20: 8 | E20: Mcc Account | F20: TRUE | G20: TRUE | H20: TRUE | I20: TRUE | J20: All good
D21: 9 | E21: Expand account to search engines beyond Google Ads | F21: FALSE | G21: FALSE | H21: FALSE | I21: FALSE | J21: Only goole ads in place | K21: First focus by optimizing account before copying towards Bing
D22: 10 | E22: Implement broad match keywords | F22: FALSE | G22: FALSE | H22: FALSE | I22: FALSE | J22: Not in place yet
D23: 11 | E23: Implement DSA ad groups | F23: FALSE | G23: FALSE | H23: FALSE | I23: FALSE | J23: Not in place yet
B24: =COUNTIF(F24:I26,TRUE)/COUNTA(F24:I26) -> 0 | C24: Champion | D24: 12 | E24: Feed based DSA ad groups | J24: Not applicable as no feed related company
D25: 13 | E25: Third party tooling for using feed based keywords | F25: FALSE | G25: FALSE | H25: FALSE | I25: FALSE | J25: No tooling in place for this | K25: Find a tooling (RFP) to optimize campagin setups
D26: 14 | E26: Use business feeds to create large keyword range | J26: Not applicable as no feed related company
B27: 2
C28: Message | F28: =IFERROR(__xludf.DUMMYFUNCTION("SPARKLINE(COUNTIF(F30:I33,TRUE),{""charttype"",""bar"";""max"",COUNTA(F30:I33);""color1"",""green""})"),"") | K28: =COUNTIF(F30:I33,TRUE)/COUNTA(F30:I33) -> 0.375
B30: =COUNTIF(F30:I30,TRUE)/COUNTA(E30:I30) -> 0.8 | C30: Basic | D30: 1 | E30: Ad group tailored ads | F30: TRUE | G30: TRUE | H30: TRUE | I30: TRUE | J30: All good
B31: =COUNTIF(F31:I31,TRUE)/COUNTA(E31:I31) -> 0.4 | C31: Advanced | D31: 2 | E31: RSA reflect steps in customer journey | F31: TRUE | G31: TRUE | H31: FALSE | I31: FALSE | J31: For DE&UK no steps yet | K31: Implement same strategy for all markets
B32: =COUNTIF(F32:I32,TRUE)/COUNTA(E32:I32) -> 0 | C32: Expert | D32: 3 | E32: Customer based RSAs based on broad contextual signals | F32: FALSE | G32: FALSE | H32: FALSE | I32: FALSE | J32: Not in place yet
B33: =COUNTIF(F33:I33,TRUE)/COUNTA(E33:I33) -> 0 | C33: Champion | D33: 4 | E33: Tailored ad text by using contextual signals | F33: FALSE | G33: FALSE | H33: FALSE | I33: FALSE | J33: Not in place yet
B35: SUMMARY (relevance to be adjusted to client needs) | M35: << in the column on the left you can decide if a certain topic is more or less important compared to others - to decide how important it is for the total score of a client Example given: Feed management is not always relevant for a company (B2B). You can give the relevance a score of 0 and it won't be calculated in the total average score Default setting: all topics at 100%
E37: Topic | F37: Topic relevance 0-100% | K37: Total score
C39: 1 | E39: =C11 -> Keywords | F39: 1 | J39: =IFERROR(__xludf.DUMMYFUNCTION("F11"),"") | K39: =K11 -> 0.35416667
C41: 2 | E41: =C28 -> Message | F41: 0.6 | J41: =IFERROR(__xludf.DUMMYFUNCTION("F28"),"") | K41: =K28 -> 0.375
C43: 3
C45: 4
C47: 5
C49: 6
C51: 7
C53: 8
C55: 9
C57: 10
...

Sheet (WIP) How to use this document
C3: Internal use: | D3: How to work with digital maturity assesment
C5: Tab | D5: Action | E5: Comment
B6: 1 | C6: General | D6: Always make a copy of this document before working in it
B7: 2 | C7: General | D7: Start with removing tabs you don't use (tip - hide them) | E7: The client shouldn't see the maturity model for other disciplines (easy to "do it themselves)
B8: 3 | C8: Exec Summary | D8: Remove the score in the exec summary view (not the chart) | E8: The reason why - the client sees you offer more then only one discipline (if we only offer 1 discipline)
B9: 4 | C9: Exec Summary | D9: Removing the score can be down in rule 14/15 of the exec summary (score is in white)
B10: 5 | C10: Exec Summary | D10: Flags - change the country name above the flag
B11: 6 | C11: Discipline | D11: Calculation: add new rules below or above a field > double check calculation | E11: If there already 2 rules - add one below the first one (will be automated)
B12: 7 | C12: Discipline | D12: Total score is a weighted sum of all the "chapters" (the ones in green)
B13: 8 | C13: Discipline

Sheet Exec. sum.
B2: Tasks done | E2: Open tasks | Q2: France | R2: Netherlands | T2: Germany | U2: Belgium | W2: United Kingdom | X2: United States | Z2: Italy
Q3: =IFERROR(__xludf.DUMMYFUNCTION("IMAGE(""https:""&IMPORTXML(""https://en.wikipedia.org/wiki/Gallery_of_sovereign_state_flags"",""//img/@src[contains(.,'""&SUBSTITUTE(Q2,"" "",""_"")&""' )]""))"),"") | R3: =IFERROR(__xludf.DUMMYFUNCTION("IMAGE(""https:""&IMPORTXML(""https://en.wikipedia.org/wiki/Gallery_of_sovereign_state_flags"",""//img/@src[contains(.,'""&SUBSTITUTE(R2,"" "",""_"")&""' )]""))"),"") | T3: =IFERROR(__xludf.DUMMYFUNCTION("IMAGE(""https:""&IMPORTXML(""https://en.wikipedia.org/wiki/Gallery_of_sovereign_state_flags"",""//img/@src[contains(.,'""&SUBSTITUTE(T2,"" "",""_"")&""' )]""))"),"") | U3: =IFERROR(__xludf.DUMMYFUNCTION("IMAGE(""https:""&IMPORTXML(""https://en.wikipedia.org/wiki/Gallery_of_sovereign_state_flags"",""//img/@src[contains(.,'""&SUBSTITUTE(U2,"" "",""_"")&""' )]""))"),"") | W3: =IFERROR(__xludf.DUMMYFUNCTION("IMAGE(""https:""&IMPORTXML(""https://en.wikipedia.org/wiki/Gallery_of_sovereign_state_flags"",""//img/@src[contains(.,'""&SUBSTITUTE(W2,"" "",""_"")&""' )]""))"),"") | X3: =IFERROR(__xludf.DUMMYFUNCTION("IMAGE(""https:""&IMPORTXML(""https://en.wikipedia.org/wiki/Gallery_of_sovereign_state_flags"",""//img/@src[contains(.,'""&SUBSTITUTE(X2,"" "",""_"")&""' )]""))"),"") | Z3: =IFERROR(__xludf.DUMMYFUNCTION("IMAGE(""https:""&IMPORTXML(""https://en.wikipedia.org/wiki/Gallery_of_sovereign_state_flags"",""//img/@src[contains(.,'""&SUBSTITUTE(Z2,"" "",""_"")&""' )]""))"),"")
C4: ='SEA - Google Ads'!M3+'SEA - Bing'!M3+META!M3+PINTEREST!M3+SEO!M3+'(WIP) CRO/UX'!M3+'Web Analytics'!M3+'DV360'!M3+'(WIP) LINKEDIN'!M3+'AI for SEO'!N3 -> #REF! | F4: ='SEA - Google Ads'!N3+'SEA - Bing'!N3+META!N3+PINTEREST!N3+SEO!N3+'(WIP) CRO/UX'!N3+'Web Analytics'!N3+'DV360'!N3+'(WIP) LINKEDIN'!N3+'AI for SEO'!N3 -> #REF! | Q4: FR | R4: NL | T4: DE | U4: BE | W4: UK | X4: US | Z4: IT
L5: The amount of tasks completed | Q5: TRUE | R5: TRUE | T5: TRUE | U5: TRUE | W5: TRUE | X5: TRUE | Z5: TRUE
Q6: ='SEA - Google Ads'!F4+'SEA - Bing'!F4+META!F4+PINTEREST!F4+SEO!F4+'(WIP) CRO/UX'!F4+'Web Analytics'!F4+'DV360'!F4+'(WIP) LINKEDIN'!F4 -> #REF! | R6: ='SEA - Google Ads'!G4+'SEA - Bing'!G4+META!G4+PINTEREST!G4+SEO!G4+'(WIP) CRO/UX'!G4+'Web Analytics'!G4+'DV360'!G4+'(WIP) LINKEDIN'!G4 -> #REF! | T6: ='SEA - Google Ads'!H4+'SEA - Bing'!H4+META!H4+PINTEREST!H4+SEO!H4+'(WIP) CRO/UX'!H4+'Web Analytics'!H4+'DV360'!H4+'(WIP) LINKEDIN'!H4 -> #REF! | U6: ='SEA - Google Ads'!I4+'SEA - Bing'!I4+META!I4+PINTEREST!I4+SEO!I4+'(WIP) CRO/UX'!I4+'Web Analytics'!I4+'DV360'!I4+'(WIP) LINKEDIN'!I4 -> #REF! | W6: ='SEA - Google Ads'!J4+'SEA - Bing'!J4+META!J4+PINTEREST!J4+SEO!J4+'(WIP) CRO/UX'!J4+'Web Analytics'!J4+'DV360'!J4+'(WIP) LINKEDIN'!J4 -> #REF! | X6: ='SEA - Google Ads'!K4+'SEA - Bing'!K4+META!K4+PINTEREST!K4+SEO!K4+'(WIP) CRO/UX'!K4+'Web Analytics'!K4+'DV360'!K4+'(WIP) LINKEDIN'!K4 -> #REF! | Z6: ='SEA - Google Ads'!L4+'SEA - Bing'!L4+META!L4+PINTEREST!L4+SEO!L4+'(WIP) CRO/UX'!L4+'Web Analytics'!L4+'DV360'!L4+'(WIP) LINKEDIN'!L4 -> #REF!
L7: The amount of open tasks | Q7: FALSE | R7: FALSE | T7: FALSE | U7: FALSE | W7: FALSE | X7: FALSE | Z7: FALSE
B10: Overall maturity level | E10: Paid Search | H10: Paid Search | K10: LinkedIn | N10: DV360 | Q10: Meta | T10: Pinterest | W10: SEO | Z10: Web Analytics | AC10: CRO / UX | AF10: AI
B12: =IF(C14<30,"Basic",IF(C14<60,"Advanced",IF(C14<84,"Expert",IF(C14>85,"Champion")))) -> Basic | E12: =IF(F14<30,"Basic",IF(F14<60,"Advanced",IF(F14<84,"Expert",IF(F14>85,"Champion")))) -> Basic | H12: =IF(I14<30,"Basic",IF(I14<60,"Advanced",IF(I14<84,"Expert",IF(I14>85,"Champion")))) -> Basic | K12: =IF(L14<30,"Basic",IF(L14<60,"Advanced",IF(L14<84,"Expert",IF(L14>85,"Champion")))) -> Basic | N12: =IF(O14<30,"Basic",IF(O14<60,"Advanced",IF(O14<84,"Expert",IF(O14>85,"Champion")))) -> Basic | Q12: =IF(R14<30,"Basic",IF(R14<60,"Advanced",IF(R14<84,"Expert",IF(R14>85,"Champion")))) -> Basic | T12: =IF(U14<30,"Basic",IF(U14<60,"Advanced",IF(U14<84,"Expert",IF(U14>85,"Champion")))) -> Basic | W12: =IF(X14<30,"Basic",IF(X14<60,"Advanced",IF(X14<84,"Expert",IF(X14>85,"Champion")))) -> Basic | Z12: =IF(AA14<30,"Basic",IF(AA14<60,"Advanced",IF(AA14<84,"Expert",IF(AA14>85,"Champion")))) -> Basic | AC12: =IF(AD14<30,"Basic",IF(AD14<60,"Advanced",IF(AD14<84,"Expert",IF(AD14>85,"Champion")))) -> Basic | AF12: =IF(AH14<30,"Basic",IF(AH14<60,"Advanced",IF(AH14<84,"Expert",IF(AH14>85,"Champion")))) -> Basic
B14: =SUM(E14+H14+Q14+W14+Z14+AC14+K14+N14+T14+AF14)/10 -> 0 | C14: =B14*100 -> 0 | E14: ='SEA - Google Ads'!B4 -> 0 | F14: =E14*100 -> 0 | H14: ='SEA - Bing'!B4 -> 0 | I14: =H14*100 -> 0 | K14: ='(WIP) LINKEDIN'!B4 -> 0 | L14: =K14*100 -> 0 | N14: ='DV360'!B4 -> 0 | O14: =N14*100 -> 0 | Q14: =META!B4 -> 0 | R14: =Q14*100 -> 0 | T14: =PINTEREST!B4 -> 0 | U14: =T14*100 -> 0 | W14: =SEO!B4 -> 0 | X14: =W14*100 -> 0 | Z14: ='Web Analytics'!B4 -> 0 | AA14: =Z14*100 -> 0 | AC14: =CROUX!B4 -> 0 | AD14: =AC14*100 -> 0 | AF14: ='AI for SEO'!B4 -> 0 | AG14: =AF14*100 -> 0 | AH14: =AF14*100 -> 0
B25: Q1 | H25: Q2 | N25: Q3 | T25: Q4
C26: Action | F26: Status | H26: Action | L26: Status | N26: Action | R26: Status | T26: Action | X26: Status
B27: Prio 1
B28: Prio 2
B29: Prio 3
B30: Prio 4
B31: Prio 5
B32: Prio 6

Sheet SEA - Google Ads
E2: MUST READ: How to use? 1. Only click a checkbox when the topic on the left - is 100% completed 2. Don't check the box if you "just" checked the topic if it was applicable 3. The same topic can be in multiple stages (different levels of maturity) | F2: FR | G2: NL | H2: DE | I2: BE | J2: UK | K2: US | L2: IT | M2: Adaptation topics (V) | N2: Topics not finalized (X) | P2: Last updated at 15/11/2023 by Sjoerd Lops & Valeria Briganti
F3: TRUE | G3: TRUE | H3: TRUE | I3: TRUE | J3: TRUE | K3: TRUE | L3: TRUE | M3: =(COUNTIF(F:L,TRUE))-COUNTIF(F3:L3,true) -> 0 | N3: =COUNTIF(F:L,FALSE) -> 623
B4: =N154 -> 0 | F4: =COUNTIF(F:F,TRUE)-1 -> 0 | G4: =COUNTIF(G:G,TRUE)-1 -> 0 | H4: =COUNTIF(H:H,TRUE)-1 -> 0 | I4: =COUNTIF(I:I,TRUE)-1 -> 0 | J4: =COUNTIF(J:J,TRUE)-1 -> 0 | K4: =COUNTIF(K:K,TRUE)-1 -> 0 | L4: =COUNTIF(L:L,TRUE)-1 -> 0
F6: =COUNTIF(F:F,FALSE) -> 89 | G6: =COUNTIF(G:G,FALSE) -> 89 | H6: =COUNTIF(H:H,FALSE) -> 89 | I6: =COUNTIF(I:I,FALSE) -> 89 | J6: =COUNTIF(J:J,FALSE) -> 89 | K6: =COUNTIF(K:K,FALSE) -> 89 | L6: =COUNTIF(L:L,FALSE) -> 89
C8: Maturity | D8: # | E8: Topics | F8: FR | G8: NL | H8: DE | I8: ES | J8: UK | K8: US | L8: IT | M8: Details | N8: Next steps
E9: If a topic is not relevant for the client - delete the checkbox | F9: Only check a box if the topic is fully integrated | M9: Explain what the issue is if not checked | N9: What would be the next steps to finalize the topic
B10: 1
C11: Keywords | F11: =IFERROR(__xludf.DUMMYFUNCTION("SPARKLINE(COUNTIF(F13:L26,TRUE),{""charttype"",""bar"";""max"",COUNTA(F13:L26);""color1"",""green""})"),"") | N11: =COUNTIF(F13:L26,TRUE)/COUNTA(F13:L26) -> 0 | P11: Commentbox for feedback
B13: =COUNTIF(F13:L17,TRUE)/COUNTA(F13:L17) -> 0 | C13: Basic | D13: 1 | E13: Low amount of keywords; generic keywords without including searc intent | F13: FALSE | G13: FALSE | H13: FALSE | I13: FALSE | J13: FALSE | K13: FALSE | L13: FALSE
D14: 2 | E14: Account structure (based on Hagakure) | F14: FALSE | G14: FALSE | H14: FALSE | I14: FALSE | J14: FALSE | K14: FALSE | L14: FALSE
D15: 3 | E15: Keyword research | F15: FALSE | G15: FALSE | H15: FALSE | I15: FALSE | J15: FALSE | K15: FALSE | L15: FALSE
D16: 4 | E16: Standard Namig Convention | F16: FALSE | G16: FALSE | H16: FALSE | I16: FALSE | J16: FALSE | K16: FALSE | L16: FALSE
D17: 5 | E17: Set-up base range of keywords | F17: FALSE | G17: FALSE | H17: FALSE | I17: FALSE | J17: FALSE | K17: FALSE | L17: FALSE
B18: =COUNTIF(F18:L19,TRUE)/COUNTA(F18:L19) -> 0 | C18: Advanced | D18: 6 | E18: Campaign segmentation based on customer journey | F18: FALSE | G18: FALSE | H18: FALSE | I18: FALSE | J18: FALSE | K18: FALSE | L18: FALSE
D19: 7 | E19: Negative keyword list | F19: FALSE | G19: FALSE | H19: FALSE | I19: FALSE | J19: FALSE | K19: FALSE | L19: FALSE
B20: =COUNTIF(F20:L23,TRUE)/COUNTA(F20:L23) -> 0 | C20: Expert | D20: 8 | E20: Mcc Account | F20: FALSE | G20: FALSE | H20: FALSE | I20: FALSE | J20: FALSE | K20: FALSE | L20: FALSE
D21: 9 | E21: Expand account to search engines beyond Google Ads | F21: FALSE | G21: FALSE | H21: FALSE | I21: FALSE | J21: FALSE | K21: FALSE | L21: FALSE
D22: 10 | E22: Implement broad match keywords | F22: FALSE | G22: FALSE | H22: FALSE | I22: FALSE | J22: FALSE | K22: FALSE | L22: FALSE
D23: 11 | E23: Implement DSA ad groups | F23: FALSE | G23: FALSE | H23: FALSE | I23: FALSE | J23: FALSE | K23: FALSE | L23: FALSE
B24: =COUNTIF(F24:L26,TRUE)/COUNTA(F24:L26) -> 0 | C24: Champion | D24: 12 | E24: Feed based DSA ad groups | F24: FALSE | G24: FALSE | H24: FALSE | I24: FALSE | J24: FALSE | K24: FALSE | L24: FALSE
D25: 13 | E25: Third party tooling for using feed based keywords | F25: FALSE | G25: FALSE | H25: FALSE | I25: FALSE | J25: FALSE | K25: FALSE | L25: FALSE
D26: 14 | E26: Use business feeds to create large keyword range | F26: FALSE | G26: FALSE | H26: FALSE | I26: FALSE | J26: FALSE | K26: FALSE | L26: FALSE
B27: 2
C28: Audiences / targeting | F28: =IFERROR(__xludf.DUMMYFUNCTION("SPARKLINE(COUNTIF(F30:L40,TRUE),{""charttype"",""bar"";""max"",COUNTA(F30:L40);""color1"",""green""})"),"") | N28: =COUNTIF(F30:L40,TRUE)/COUNTA(F30:L40) -> 0
B30: =COUNTIF(F30:L30,TRUE)/COUNTA(E30:L30) -> 0 | C30: Basic | D30: 1 | E30: Basic demographics and audiences | F30: FALSE | G30: FALSE | H30: FALSE | I30: FALSE | J30: FALSE | K30: FALSE | L30: FALSE
B31: =COUNTIF(F31:L35,TRUE)/COUNTA(E31:L35) -> 0 | C31: Advanced | D31: 2 | E31: Location targeting | F31: FALSE | G31: FALSE | H31: FALSE | I31: FALSE | J31: FALSE | K31: FALSE | L31: FALSE
D32: 3 | E32: Remarketing lists | F32: FALSE | G32: FALSE | H32: FALSE | I32: FALSE | J32: FALSE | K32: FALSE | L32: FALSE
D33: 4 | E33: Import Google Analytics remarketing audiences | F33: FALSE | G33: FALSE | H33: FALSE | I33: FALSE | J33: FALSE | K33: FALSE | L33: FALSE
D34: 5 | E34: Import Google Analyics audiences based on purchase behaviour / category interest | F34: FALSE | G34: FALSE | H34: FALSE | I34: FALSE | J34: FALSE | K34: FALSE | L34: FALSE
D35: 6 | E35: Import Google Analyics audiences based on page visits | F35: FALSE | G35: FALSE | H35: FALSE | I35: FALSE | J35: FALSE | K35: FALSE | L35: FALSE
B36: =COUNTIF(F36:L38,TRUE)/COUNTA(F36:L38) -> 0 | C36: Expert | D36: 7 | E36: Import CRM lists | F36: FALSE | G36: FALSE | H36: FALSE | I36: FALSE | J36: FALSE | K36: FALSE | L36: FALSE
D37: 8 | E37: Import Google Analyics predictive audiences | F37: FALSE | G37: FALSE | H37: FALSE | I37: FALSE | J37: FALSE | K37: FALSE | L37: FALSE
D38: 9 | E38: Incorporate all audiences above in the campaign settings | F38: FALSE | G38: FALSE | H38: FALSE | I38: FALSE | J38: FALSE | K38: FALSE | L38: FALSE
B39: =COUNTIF(F39:L40,TRUE)/COUNTA(E39:L40) -> 0 | C39: Champion | D39: 10 | E39: Use Instant BQML - Purchase, Product or Churn propensity | F39: FALSE | G39: FALSE | H39: FALSE | I39: FALSE | J39: FALSE | K39: FALSE | L39: FALSE
D40: 11 | E40: Real time CRM lists integration | F40: FALSE | G40: FALSE | H40: FALSE | I40: FALSE | J40: FALSE | K40: FALSE | L40: FALSE
B41: 3
C42: Conversion & KPI | F42: =IFERROR(__xludf.DUMMYFUNCTION("SPARKLINE(COUNTIF(F44:L55,TRUE),{""charttype"",""bar"";""max"",COUNTA(F44:L55);""color1"",""green""})"),"") | N42: =COUNTIF(F44:L55,TRUE)/COUNTA(F44:L55) -> 0
B44: =COUNTIF(F44:L46,TRUE)/COUNTA(F44:L46) -> 0 | C44: Basic | D44: 1 | E44: Conversion set-up | F44: FALSE | G44: FALSE | H44: FALSE | I44: FALSE | J44: FALSE | K44: FALSE | L44: FALSE
D45: 2 | E45: Conversion tags are implemented in GTM | F45: FALSE | G45: FALSE | H45: FALSE | I45: FALSE | J45: FALSE | K45: FALSE | L45: FALSE
D46: 3 | E46: Focus on increasing amount of conversions | F46: FALSE | G46: FALSE | H46: FALSE | I46: FALSE | J46: FALSE | K46: FALSE | L46: FALSE
...

Sheet SEA - Bing
E2: MUST READ: How to use? 1. Only click a checkbox when the topic on the left - is 100% completed 2. Don't check the box if you "just" checked the topic if it was applicable 3. The same topic can be in multiple stages (different levels of maturity) | F2: FR | G2: NL | H2: DE | I2: BE | J2: UK | K2: US | L2: IT | M2: Adaptation topics (V) | N2: Topics not finalized (X) | P2: Last updated at 22/09/2023 by Sjoerd Lops
F3: TRUE | G3: TRUE | H3: TRUE | I3: TRUE | J3: TRUE | K3: TRUE | L3: TRUE | M3: =(COUNTIF(F:L,TRUE))-COUNTIF(F3:L3,true) -> 0 | N3: =COUNTIF(F:L,FALSE) -> 448
B4: =N123 -> 0 | F4: =COUNTIF(F:F,TRUE)-1 -> 0 | G4: =COUNTIF(G:G,TRUE)-1 -> 0 | H4: =COUNTIF(H:H,TRUE)-1 -> 0 | I4: =COUNTIF(I:I,TRUE)-1 -> 0 | J4: =COUNTIF(J:J,TRUE)-1 -> 0 | K4: =COUNTIF(K:K,TRUE)-1 -> 0 | L4: =COUNTIF(L:L,TRUE)-1 -> 0
F6: =COUNTIF(F:F,FALSE) -> 64 | G6: =COUNTIF(G:G,FALSE) -> 64 | H6: =COUNTIF(H:H,FALSE) -> 64 | I6: =COUNTIF(I:I,FALSE) -> 64 | J6: =COUNTIF(J:J,FALSE) -> 64 | K6: =COUNTIF(K:K,FALSE) -> 64 | L6: =COUNTIF(L:L,FALSE) -> 64
C8: Maturity | D8: # | E8: Topics | F8: FR | G8: NL | H8: DE | I8: BE | J8: UK | K8: US | L8: IT | M8: Details | N8: Comments / Action
E9: If a topic is not relevant for the client - delete the checkbox | F9: Only check a box if the topic is fully integrated | M9: Explain what the issue is if not checked | N9: What would be the next steps to finalize the topic
B10: 1
C11: Keywords | F11: =IFERROR(__xludf.DUMMYFUNCTION("SPARKLINE(COUNTIF(F13:L26,TRUE),{""charttype"",""bar"";""max"",COUNTA(F13:L26);""color1"",""green""})"),"") | N11: =COUNTIF(F13:L26,TRUE)/COUNTA(F13:L26) -> 0 | P11: Commentbox for feedback
B13: =COUNTIF(F13:L17,TRUE)/COUNTA(F13:L17) -> 0 | C13: Basic | D13: 1 | E13: Low amount of keywords; generic keywords without including searc intent | F13: FALSE | G13: FALSE | H13: FALSE | I13: FALSE | J13: FALSE | K13: FALSE | L13: FALSE
D14: 2 | E14: Account structure (based on Hagakure) | F14: FALSE | G14: FALSE | H14: FALSE | I14: FALSE | J14: FALSE | K14: FALSE | L14: FALSE
D15: 3 | E15: Keyword research | F15: FALSE | G15: FALSE | H15: FALSE | I15: FALSE | J15: FALSE | K15: FALSE | L15: FALSE
D16: 4 | E16: Standard Namig Convention | F16: FALSE | G16: FALSE | H16: FALSE | I16: FALSE | J16: FALSE | K16: FALSE | L16: FALSE
D17: 5 | E17: Set-up base range of keywords | F17: FALSE | G17: FALSE | H17: FALSE | I17: FALSE | J17: FALSE | K17: FALSE | L17: FALSE
B18: =COUNTIF(F18:L19,TRUE)/COUNTA(F18:L19) -> 0 | C18: Advanced | D18: 6 | E18: Campaign segmentation based on customer journey | F18: FALSE | G18: FALSE | H18: FALSE | I18: FALSE | J18: FALSE | K18: FALSE | L18: FALSE
D19: 7 | E19: Negative keyword list | F19: FALSE | G19: FALSE | H19: FALSE | I19: FALSE | J19: FALSE | K19: FALSE | L19: FALSE
B20: =COUNTIF(F20:L23,TRUE)/COUNTA(F20:L23) -> 0 | C20: Expert | D20: 8 | E20: Mcc Account | F20: FALSE | G20: FALSE | H20: FALSE | I20: FALSE | J20: FALSE | K20: FALSE | L20: FALSE
D21: 9 | E21: Expand account to search engines beyond Google Ads | F21: FALSE | G21: FALSE | H21: FALSE | I21: FALSE | J21: FALSE | K21: FALSE | L21: FALSE
D22: 10 | E22: Implement broad match keywords | F22: FALSE | G22: FALSE | H22: FALSE | I22: FALSE | J22: FALSE | K22: FALSE | L22: FALSE
D23: 11 | E23: Implement DSA ad groups | F23: FALSE | G23: FALSE | H23: FALSE | I23: FALSE | J23: FALSE | K23: FALSE | L23: FALSE
B24: =COUNTIF(F24:L26,TRUE)/COUNTA(F24:L26) -> 0 | C24: Champion | D24: 12 | E24: Feed based DSA ad groups | F24: FALSE | G24: FALSE | H24: FALSE | I24: FALSE | J24: FALSE | K24: FALSE | L24: FALSE
D25: 13 | E25: Third party tooling for using feed based keywords | F25: FALSE | G25: FALSE | H25: FALSE | I25: FALSE | J25: FALSE | K25: FALSE | L25: FALSE
D26: 14 | E26: Use business feeds to create large keyword range | F26: FALSE | G26: FALSE | H26: FALSE | I26: FALSE | J26: FALSE | K26: FALSE | L26: FALSE
B27: 2
C28: Audiences / targeting | F28: =IFERROR(__xludf.DUMMYFUNCTION("SPARKLINE(COUNTIF(F30:L38,TRUE),{""charttype"",""bar"";""max"",COUNTA(F30:L38);""color1"",""green""})"),"") | N28: =COUNTIF(F30:L38,TRUE)/COUNTA(F30:L38) -> 0
B30: =COUNTIF(F30:L30,TRUE)/COUNTA(E30:L30) -> 0 | C30: Basic | D30: 1 | E30: Basic demographics and audiences | F30: FALSE | G30: FALSE | H30: FALSE | I30: FALSE | J30: FALSE | K30: FALSE | L30: FALSE
B31: =COUNTIF(F31:L34,TRUE)/COUNTA(E31:L34) -> 0 | C31: Advanced | D31: 2 | E31: Location targetting | F31: FALSE | G31: FALSE | H31: FALSE | I31: FALSE | J31: FALSE | K31: FALSE | L31: FALSE
D32: 3 | E32: Remarketing lists | F32: FALSE | G32: FALSE | H32: FALSE | I32: FALSE | J32: FALSE | K32: FALSE | L32: FALSE
D33: 4 | E33: Import Google Analytics remarketing audiences | F33: FALSE | G33: FALSE | H33: FALSE | I33: FALSE | J33: FALSE | K33: FALSE | L33: FALSE
D34: 5 | E34: Import Google Analyics audiences based on page visits | F34: FALSE | G34: FALSE | H34: FALSE | I34: FALSE | J34: FALSE | K34: FALSE | L34: FALSE
B35: =COUNTIF(F35:L35,TRUE)/COUNTA(E35:L35) -> 0 | C35: Expert | D35: 6 | E35: Incorporate all audiences above in the campaignsettings | F35: FALSE | G35: FALSE | H35: FALSE | I35: FALSE | J35: FALSE | K35: FALSE | L35: FALSE
B36: =COUNTIF(F36:L38,TRUE)/COUNTA(E36:L38) -> 0 | C36: Champion | D36: 7 | E36: Import CRM lists | F36: FALSE | G36: FALSE | H36: FALSE | I36: FALSE | J36: FALSE | K36: FALSE | L36: FALSE
D37: 8 | E37: Import 1st party data based audiences | F37: FALSE | G37: FALSE | H37: FALSE | I37: FALSE | J37: FALSE | K37: FALSE | L37: FALSE
D38: 9 | E38: Create custom look-a-like audiences based on 1st party | F38: FALSE | G38: FALSE | H38: FALSE | I38: FALSE | J38: FALSE | K38: FALSE | L38: FALSE
B39: 3
C40: Conversion & KPI | F40: =IFERROR(__xludf.DUMMYFUNCTION("SPARKLINE(COUNTIF(F42:L52,TRUE),{""charttype"",""bar"";""max"",COUNTA(F42:L52);""color1"",""green""})"),"") | N40: =COUNTIF(F42:L52,TRUE)/COUNTA(F42:L52) -> 0
B42: =COUNTIF(F42:L44,TRUE)/COUNTA(F42:L44) -> 0 | C42: Basic | D42: 1 | E42: Conversion set-up | F42: FALSE | G42: FALSE | H42: FALSE | I42: FALSE | J42: FALSE | K42: FALSE | L42: FALSE
D43: 2 | E43: Conversion tags are implemented in GTM | F43: FALSE | G43: FALSE | H43: FALSE | I43: FALSE | J43: FALSE | K43: FALSE | L43: FALSE
D44: 3 | E44: Focus on increasing amount of conversions | F44: FALSE | G44: FALSE | H44: FALSE | I44: FALSE | J44: FALSE | K44: FALSE | L44: FALSE
B45: =COUNTIF(F45:L47,TRUE)/COUNTA(F45:L47) -> 0 | C45: Advanced | D45: 4 | E45: Conversion data (ensure conversion data) | F45: FALSE | G45: FALSE | H45: FALSE | I45: FALSE | J45: FALSE | K45: FALSE | L45: FALSE
D46: 5 | E46: Enhanced Conversions For lead generation Implemented | F46: FALSE | G46: FALSE | H46: FALSE | I46: FALSE | J46: FALSE | K46: FALSE | L46: FALSE
...

Sheet META
E2: MUST READ: How to use? 1. Only click a checkbox when the topic on the left - is 100% completed 2. Don't check the box if you "just" checked the topic if it was applicable 3. The same topic can be in multiple stages (different levels of maturity) | F2: FR | G2: NL | H2: DE | I2: BE | J2: UK | K2: US | L2: IT | M2: Adaptation topics (V) | N2: Topics not finalized (X) | P2: Last updated at 04/12/2025 by Laman Guliyeva
F3: TRUE | G3: TRUE | H3: TRUE | I3: TRUE | J3: TRUE | K3: TRUE | L3: TRUE | M3: =(COUNTIF(F:L,TRUE))-COUNTIF(F3:L3,true) -> 0 | N3: =COUNTIF(F:L,FALSE) -> 483
B4: =N122 -> 0 | F4: =COUNTIF(F:F,TRUE)-1 -> 0 | G4: =COUNTIF(G:G,TRUE)-1 -> 0 | H4: =COUNTIF(H:H,TRUE)-1 -> 0 | I4: =COUNTIF(I:I,TRUE)-1 -> 0 | J4: =COUNTIF(J:J,TRUE)-1 -> 0 | K4: =COUNTIF(K:K,TRUE)-1 -> 0 | L4: =COUNTIF(L:L,TRUE)-1 -> 0
F6: =COUNTIF(F:F,FALSE) -> 69 | G6: =COUNTIF(G:G,FALSE) -> 69 | H6: =COUNTIF(H:H,FALSE) -> 69 | I6: =COUNTIF(I:I,FALSE) -> 69 | J6: =COUNTIF(J:J,FALSE) -> 69 | K6: =COUNTIF(K:K,FALSE) -> 69 | L6: =COUNTIF(L:L,FALSE) -> 69
C8: Maturity | D8: # | E8: Topics | F8: FR | G8: NL | H8: DE | I8: BE | J8: UK | K8: US | L8: IT | M8: Details | N8: Comments / Action
E9: If a topic is not relevant for the client - delete the checkbox | F9: Only check a box if the topic is fully integrated | M9: Explain what the issue is if not checked | N9: What would be the next steps to finalize the topic
B10: 1
C11: Campaign setup | F11: =IFERROR(__xludf.DUMMYFUNCTION("SPARKLINE(COUNTIF(F13:L23,TRUE),{""charttype"",""bar"";""max"",COUNTA(F13:L23);""color1"",""green""})"),"") | N11: =COUNTIF(F13:L23,TRUE)/COUNTA(F13:L23) -> 0 | P11: Commentbox for feedback
B13: 0 | C13: Basic | D13: 1 | E13: Campaign setup based on algorithms | F13: FALSE | G13: FALSE | H13: FALSE | I13: FALSE | J13: FALSE | K13: FALSE | L13: FALSE
D14: 2 | E14: Organized structure | F14: FALSE | G14: FALSE | H14: FALSE | I14: FALSE | J14: FALSE | K14: FALSE | L14: FALSE
B15: =COUNTIF(F15:L20,TRUE)/COUNTA(E15:L20) -> 0 | C15: Advanced | D15: 3 | E15: Simple structure (easy to understand) | F15: FALSE | G15: FALSE | H15: FALSE | I15: FALSE | J15: FALSE | K15: FALSE | L15: FALSE
D16: 4 | E16: Naming convention on campaign level | F16: FALSE | G16: FALSE | H16: FALSE | I16: FALSE | J16: FALSE | K16: FALSE | L16: FALSE
D17: 5 | E17: Naming convention on ad group level | F17: FALSE | G17: FALSE | H17: FALSE | I17: FALSE | J17: FALSE | K17: FALSE | L17: FALSE
D18: 6 | E18: Naming convention on ad level | F18: FALSE | G18: FALSE | H18: FALSE | I18: FALSE | J18: FALSE | K18: FALSE | L18: FALSE
D19: 7 | E19: Structure in line with offer on the website | F19: FALSE | G19: FALSE | H19: FALSE | I19: FALSE | J19: FALSE | K19: FALSE | L19: FALSE
D20: 8 | E20: Lookback windows | F20: FALSE | G20: FALSE | H20: FALSE | I20: FALSE | J20: FALSE | K20: FALSE | L20: FALSE
B21: =COUNTIF(F21:G21,TRUE)/COUNTA(F21:G21) -> 0 | C21: Expert | D21: 9 | E21: Advantage+ Sales Plus campaigns for ecommerce | F21: FALSE | G21: FALSE | H21: FALSE | I21: FALSE | J21: FALSE | K21: FALSE | L21: FALSE
B22: =COUNTIF(F22:L23,TRUE)/COUNTA(L22:BQ23) -> 0 | C22: Champion | D22: 9 | E22: Build campaign setups via Excel or external tooling (e.g. Smartly / ByCape.io) | F22: FALSE | G22: FALSE | H22: FALSE | I22: FALSE | J22: FALSE | K22: FALSE | L22: FALSE
D23: 10 | E23: Have a naming convention tool integration (grasp) | F23: FALSE | G23: FALSE | H23: FALSE | I23: FALSE | J23: FALSE | K23: FALSE | L23: FALSE
B24: 2
C25: Audiences & targeting | F25: =IFERROR(__xludf.DUMMYFUNCTION("SPARKLINE(COUNTIF(F27:L41,TRUE),{""charttype"",""bar"";""max"",COUNTA(F27:L41);""color1"",""green""})"),"") | N25: =COUNTIF(F27:L41,TRUE)/COUNTA(F27:L41) -> 0
B27: =COUNTIF(F27:L31,TRUE)/COUNTA(F27:L31) -> 0 | C27: Basic | D27: 1 | E27: Language targeting | F27: FALSE | G27: FALSE | H27: FALSE | I27: FALSE | J27: FALSE | K27: FALSE | L27: FALSE
D28: 2 | E28: Age targeting | F28: FALSE | G28: FALSE | H28: FALSE | I28: FALSE | J28: FALSE | K28: FALSE | L28: FALSE
D29: 3 | E29: Demographic targeting | F29: FALSE | G29: FALSE | H29: FALSE | I29: FALSE | J29: FALSE | K29: FALSE | L29: FALSE
D30: 4 | E30: Specific placement targeting | F30: FALSE | G30: FALSE | H30: FALSE | I30: FALSE | J30: FALSE | K30: FALSE | L30: FALSE
D31: 5 | E31: Dedicated campaign per market | F31: FALSE | G31: FALSE | H31: FALSE | I31: FALSE | J31: FALSE | K31: FALSE | L31: FALSE
B32: =COUNTIF(F32:L35,TRUE)/COUNTA(F32:L35) -> 0 | C32: Advanced | D32: 6 | E32: Is there an audience framework in place (and used for targeting?) | F32: FALSE | G32: FALSE | H32: FALSE | I32: FALSE | J32: FALSE | K32: FALSE | L32: FALSE
D33: 7 | E33: Is there a persona in place from client side (the ideal customer) | F33: FALSE | G33: FALSE | H33: FALSE | I33: FALSE | J33: FALSE | K33: FALSE | L33: FALSE
D34: 8 | E34: Retargeting audiences | F34: FALSE | G34: FALSE | H34: FALSE | I34: FALSE | J34: FALSE | K34: FALSE | L34: FALSE
D35: 9 | E35: Inplatform audiences (followers, retarget video viewers) | F35: FALSE | G35: FALSE | H35: FALSE | I35: FALSE | J35: FALSE | K35: FALSE | L35: FALSE
B36: =COUNTIF(F36:L40,TRUE)/COUNTA(F36:L40) -> 0 | C36: Expert | D36: 10 | E36: Event based audiences (on pixel events) | F36: FALSE | G36: FALSE | H36: FALSE | I36: FALSE | J36: FALSE | K36: FALSE | L36: FALSE
D37: 11 | E37: Bid adjustments per audience | F37: FALSE | G37: FALSE | H37: FALSE | I37: FALSE | J37: FALSE | K37: FALSE | L37: FALSE
D38: 12 | E38: Customer Match audiences | F38: FALSE | G38: FALSE | H38: FALSE | I38: FALSE | J38: FALSE | K38: FALSE | L38: FALSE
D39: 13 | E39: Is the Advantage+ Audiences set up used? | F39: FALSE | G39: FALSE | H39: FALSE | I39: FALSE | J39: FALSE | K39: FALSE | L39: FALSE
D40: 14 | E40: Audience Segments established | F40: FALSE | G40: FALSE | H40: FALSE | I40: FALSE | J40: FALSE | K40: FALSE | L40: FALSE
B41: =COUNTIF(F41:L41,TRUE)/COUNTA(F41:L41) -> 0 | C41: Champion | D41: 15 | E41: Customer Data Platform (CDP) integration | F41: FALSE | G41: FALSE | H41: FALSE | I41: FALSE | J41: FALSE | K41: FALSE | L41: FALSE
B42: 3
C43: Conversion & KPI | F43: =IFERROR(__xludf.DUMMYFUNCTION("SPARKLINE(COUNTIF(F45:L54,TRUE),{""charttype"",""bar"";""max"",COUNTA(F45:L54);""color1"",""green""})"),"") | N43: =COUNTIF(F45:L57,TRUE)/COUNTA(F45:L54) -> 0
B45: =COUNTIF(F45:L48,TRUE)/COUNTA(L45:BQ48) -> 0 | C45: Basic | D45: 1 | E45: General goal for Meta (total) | F45: FALSE | G45: FALSE | H45: FALSE | I45: FALSE | J45: FALSE | K45: FALSE | L45: FALSE
D46: 2 | E46: The Meta pixel has been installed on the website | F46: FALSE | G46: FALSE | H46: FALSE | I46: FALSE | J46: FALSE | K46: FALSE | L46: FALSE
...

Sheet PINTEREST
E2: MUST READ: How to use? 1. Only click a checkbox when the topic on the left - is 100% completed 2. Don't check the box if you "just" checked the topic if it was applicable 3. The same topic can be in multiple stages (different levels of maturity) | F2: FR | G2: NL | H2: DE | I2: BE | J2: UK | K2: US | L2: IT | M2: Adaptation topics (V) | N2: Topics not finalized (X) | P2: Last updated at 06/02/2025 by Laman Guliyeva
F3: TRUE | G3: TRUE | H3: TRUE | I3: TRUE | J3: TRUE | K3: TRUE | L3: TRUE | M3: =(COUNTIF(F:L,TRUE))-COUNTIF(F3:L3,true) -> 0 | N3: =COUNTIF(F:L,FALSE) -> 413
B4: =N112 -> 0 | F4: =COUNTIF(F:F,TRUE)-1 -> 0 | G4: =COUNTIF(G:G,TRUE)-1 -> 0 | H4: =COUNTIF(H:H,TRUE)-1 -> 0 | I4: =COUNTIF(I:I,TRUE)-1 -> 0 | J4: =COUNTIF(J:J,TRUE)-1 -> 0 | K4: =COUNTIF(K:K,TRUE)-1 -> 0 | L4: =COUNTIF(L:L,TRUE)-1 -> 0
F6: =COUNTIF(F:F,FALSE) -> 59 | G6: =COUNTIF(G:G,FALSE) -> 59 | H6: =COUNTIF(H:H,FALSE) -> 59 | I6: =COUNTIF(I:I,FALSE) -> 59 | J6: =COUNTIF(J:J,FALSE) -> 59 | K6: =COUNTIF(K:K,FALSE) -> 59 | L6: =COUNTIF(L:L,FALSE) -> 59
C8: Maturity | D8: # | E8: Topics | F8: FR | G8: NL | H8: DE | I8: BE | J8: UK | K8: US | L8: IT | M8: Details | N8: Comments / Action
E9: If a topic is not relevant for the client - delete the checkbox | F9: Only check a box if the topic is fully integrated | M9: Explain what the issue is if not checked | N9: What would be the next steps to finalize the topic
B10: 1
C11: Campaign setup | F11: =IFERROR(__xludf.DUMMYFUNCTION("SPARKLINE(COUNTIF(F13:L23,TRUE),{""charttype"",""bar"";""max"",COUNTA(F13:L23);""color1"",""green""})"),"") | N11: =COUNTIF(F13:L23,TRUE)/COUNTA(F13:L23) -> 0 | P11: Commentbox for feedback
B13: =COUNTIF(F13:F14,TRUE)/COUNTA(F13:F14) -> 0 | C13: Basic | D13: 1 | E13: Campaign setup based on algorithms | F13: FALSE | G13: FALSE | H13: FALSE | I13: FALSE | J13: FALSE | K13: FALSE | L13: FALSE
D14: 2 | E14: Organized structure | F14: FALSE | G14: FALSE | H14: FALSE | I14: FALSE | J14: FALSE | K14: FALSE | L14: FALSE
B15: =COUNTIF(F15:F20,TRUE)/COUNTA(F15:F20) -> 0 | C15: Advanced | D15: 3 | E15: Simple structure (easy to understand) | F15: FALSE | G15: FALSE | H15: FALSE | I15: FALSE | J15: FALSE | K15: FALSE | L15: FALSE
D16: 4 | E16: Naming convention on campaign level | F16: FALSE | G16: FALSE | H16: FALSE | I16: FALSE | J16: FALSE | K16: FALSE | L16: FALSE
D17: 5 | E17: Naming convention on ad group level | F17: FALSE | G17: FALSE | H17: FALSE | I17: FALSE | J17: FALSE | K17: FALSE | L17: FALSE
D18: 6 | E18: Naming convention on ad level | F18: FALSE | G18: FALSE | H18: FALSE | I18: FALSE | J18: FALSE | K18: FALSE | L18: FALSE
D19: 7 | E19: Structure in line with offer on the website | F19: FALSE | G19: FALSE | H19: FALSE | I19: FALSE | J19: FALSE | K19: FALSE | L19: FALSE
D20: 8 | E20: Attribution windows | F20: FALSE | G20: FALSE | H20: FALSE | I20: FALSE | J20: FALSE | K20: FALSE | L20: FALSE
B21: =COUNTIF(F21,TRUE)/COUNTA(F21) -> 0 | C21: Expert | D21: 9 | E21: Pinterest Performance+ Campaigns | F21: FALSE | G21: FALSE | H21: FALSE | I21: FALSE | J21: FALSE | K21: FALSE | L21: FALSE
B22: =COUNTIF(F22:F23,TRUE)/COUNTA(F22:F23) -> 0 | C22: Champion | D22: 10 | E22: Build campaign setups via Excel or external tooling (e.g. Smartly / ByCape.io) | F22: FALSE | G22: FALSE | H22: FALSE | I22: FALSE | J22: FALSE | K22: FALSE | L22: FALSE
D23: 11 | E23: Have a naming convention tool integration (grasp) | F23: FALSE | G23: FALSE | H23: FALSE | I23: FALSE | J23: FALSE | K23: FALSE | L23: FALSE
B24: 2
C25: Audiences & targeting | F25: =IFERROR(__xludf.DUMMYFUNCTION("SPARKLINE(COUNTIF(F27:L40,TRUE),{""charttype"",""bar"";""max"",COUNTA(F27:L40);""color1"",""green""})"),"") | N25: =COUNTIF(F27:L40,TRUE)/COUNTA(F27:L40) -> 0
B27: =COUNTIF(F27:F30,TRUE)/COUNTA(F27:F30) -> 0 | C27: Basic | D27: 1 | E27: Language targeting | F27: FALSE | G27: FALSE | H27: FALSE | I27: FALSE | J27: FALSE | K27: FALSE | L27: FALSE
D28: 2 | E28: Age targeting | F28: FALSE | G28: FALSE | H28: FALSE | I28: FALSE | J28: FALSE | K28: FALSE | L28: FALSE
D29: 3 | E29: Demographic targeting | F29: FALSE | G29: FALSE | H29: FALSE | I29: FALSE | J29: FALSE | K29: FALSE | L29: FALSE
D30: 4 | E30: Dedicated campaign per market | F30: FALSE | G30: FALSE | H30: FALSE | I30: FALSE | J30: FALSE | K30: FALSE | L30: FALSE
B31: =COUNTIF(F31:F36,TRUE)/COUNTA(F31:F36) -> 0 | C31: Advanced | D31: 5 | E31: Is there an audience framework in place (and used for targeting?) | F31: FALSE | G31: FALSE | H31: FALSE | I31: FALSE | J31: FALSE | K31: FALSE | L31: FALSE
D32: 6 | E32: Is there a persona in place from client side (the ideal customer) | F32: FALSE | G32: FALSE | H32: FALSE | I32: FALSE | J32: FALSE | K32: FALSE | L32: FALSE
D33: 7 | E33: Pinterest Performance+ targeting activated | F33: FALSE | G33: FALSE | H33: FALSE | I33: FALSE | J33: FALSE | K33: FALSE | L33: FALSE
D34: 8 | E34: Device targeting | F34: FALSE | G34: FALSE | H34: FALSE | I34: FALSE | J34: FALSE | K34: FALSE | L34: FALSE
D35: 9 | E35: Retargeting audiences | F35: FALSE | G35: FALSE | H35: FALSE | I35: FALSE | J35: FALSE | K35: FALSE | L35: FALSE
D36: 10 | E36: Specific placement targeting | F36: FALSE | G36: FALSE | H36: FALSE | I36: FALSE | J36: FALSE | K36: FALSE | L36: FALSE
B37: =COUNTIF(F37:F39,TRUE)/COUNTA(F37:F39) -> 0 | C37: Expert | D37: 11 | E37: Inplatform audiences (followers, retarget video viewers) | F37: FALSE | G37: FALSE | H37: FALSE | I37: FALSE | J37: FALSE | K37: FALSE | L37: FALSE
D38: 12 | E38: Event based audiences (on pixel events) | F38: FALSE | G38: FALSE | H38: FALSE | I38: FALSE | J38: FALSE | K38: FALSE | L38: FALSE
D39: 14 | E39: Customer Match audiences | F39: FALSE | G39: FALSE | H39: FALSE | I39: FALSE | J39: FALSE | K39: FALSE | L39: FALSE
B40: =COUNTIF(F40,TRUE)/COUNTA(F40) -> 0 | C40: Champion | D40: 15 | E40: Customer Data Platform (CDP) integration | F40: FALSE | G40: FALSE | H40: FALSE | I40: FALSE | J40: FALSE | K40: FALSE | L40: FALSE
B41: 3
C42: Conversion & KPI | F42: =IFERROR(__xludf.DUMMYFUNCTION("SPARKLINE(COUNTIF(F44:L50,TRUE),{""charttype"",""bar"";""max"",COUNTA(F44:L50);""color1"",""green""})"),"") | N42: =COUNTIF(F44:L50,TRUE)/COUNTA(F44:L50) -> 0
B44: =COUNTIF(F44:F45,TRUE)/COUNTA(F44:F45) -> 0 | C44: Basic | D44: 1 | E44: General goal for Pinterest (total) | F44: FALSE | G44: FALSE | H44: FALSE | I44: FALSE | J44: FALSE | K44: FALSE | L44: FALSE
D45: 2 | E45: Monthly performance check in on KPI's | F45: FALSE | G45: FALSE | H45: FALSE | I45: FALSE | J45: FALSE | K45: FALSE | L45: FALSE
B46: =COUNTIF(F46:F48,TRUE)/COUNTA(F46:F48) -> 0 | C46: Advanced | D46: 3 | E46: A clear KPI framework with goals per funnel | F46: FALSE | G46: FALSE | H46: FALSE | I46: FALSE | J46: FALSE | K46: FALSE | L46: FALSE
...

Sheet TikTok
E2: MUST READ: How to use? 1. Only click a checkbox when the topic on the left - is 100% completed 2. Don't check the box if you "just" checked the topic if it was applicable 3. The same topic can be in multiple stages (different levels of maturity) | F2: FR | G2: NL | H2: DE | I2: BE | J2: UK | K2: US | L2: IT | M2: Adaptation topics (V) | N2: Topics not finalized (X) | P2: Last updated at 15/12/2025 by Laman Guliyeva
F3: TRUE | G3: TRUE | H3: TRUE | I3: TRUE | J3: TRUE | K3: TRUE | L3: TRUE | M3: =(COUNTIF(F:L,TRUE))-COUNTIF(F3:L3,true) -> 0 | N3: =COUNTIF(F:L,FALSE) -> 420
B4: =N109 -> 0 | F4: =COUNTIF(F:F,TRUE)-1 -> 0 | G4: =COUNTIF(G:G,TRUE)-1 -> 0 | H4: =COUNTIF(H:H,TRUE)-1 -> 0 | I4: =COUNTIF(I:I,TRUE)-1 -> 0 | J4: =COUNTIF(J:J,TRUE)-1 -> 0 | K4: =COUNTIF(K:K,TRUE)-1 -> 0 | L4: =COUNTIF(L:L,TRUE)-1 -> 0
F6: =COUNTIF(F:F,FALSE) -> 60 | G6: =COUNTIF(G:G,FALSE) -> 60 | H6: =COUNTIF(H:H,FALSE) -> 60 | I6: =COUNTIF(I:I,FALSE) -> 60 | J6: =COUNTIF(J:J,FALSE) -> 60 | K6: =COUNTIF(K:K,FALSE) -> 60 | L6: =COUNTIF(L:L,FALSE) -> 60
C8: Maturity | D8: # | E8: Topics | F8: FR | G8: NL | H8: DE | I8: BE | J8: UK | K8: US | L8: IT | M8: Details | N8: Comments / Action
E9: If a topic is not relevant for the client - delete the checkbox | F9: Only check a box if the topic is fully integrated | M9: Explain what the issue is if not checked | N9: What would be the next steps to finalize the topic
B10: 1
C11: Campaign setup | F11: =IFERROR(__xludf.DUMMYFUNCTION("SPARKLINE(COUNTIF(F13:L24,TRUE),{""charttype"",""bar"";""max"",COUNTA(F13:L24);""color1"",""green""})"),"") | N11: =COUNTIF(F13:L24,TRUE)/COUNTA(F13:L24) -> 0 | P11: Commentbox for feedback
B13: =COUNTIF(F13:L14,TRUE)/COUNTA(F13:L14) -> 0 | C13: Basic | D13: 1 | E13: Campaign setup based on algorithms | F13: FALSE | G13: FALSE | H13: FALSE | I13: FALSE | J13: FALSE | K13: FALSE | L13: FALSE
D14: 2 | E14: Organized structure | F14: FALSE | G14: FALSE | H14: FALSE | I14: FALSE | J14: FALSE | K14: FALSE | L14: FALSE
B15: =COUNTIF(F15:L20,TRUE)/COUNTA(J15:L20) -> 0 | C15: Advanced | D15: 3 | E15: Simple structure (easy to understand) | F15: FALSE | G15: FALSE | H15: FALSE | I15: FALSE | J15: FALSE | K15: FALSE | L15: FALSE
D16: 4 | E16: Naming convention on campaign level | F16: FALSE | G16: FALSE | H16: FALSE | I16: FALSE | J16: FALSE | K16: FALSE | L16: FALSE
D17: 5 | E17: Naming convention on ad group level | F17: FALSE | G17: FALSE | H17: FALSE | I17: FALSE | J17: FALSE | K17: FALSE | L17: FALSE
D18: 6 | E18: Naming convention on ad level | F18: FALSE | G18: FALSE | H18: FALSE | I18: FALSE | J18: FALSE | K18: FALSE | L18: FALSE
D19: 7 | E19: Structure in line with offer on the website | F19: FALSE | G19: FALSE | H19: FALSE | I19: FALSE | J19: FALSE | K19: FALSE | L19: FALSE
D20: 8 | E20: Attribution windows | F20: FALSE | G20: FALSE | H20: FALSE | I20: FALSE | J20: FALSE | K20: FALSE | L20: FALSE
B21: =COUNTIF(F21:JL22,TRUE)/COUNTA(F21:L22) -> 0 | C21: Expert | D21: 9 | E21: Smart+ Campaign | F21: FALSE | G21: FALSE | H21: FALSE | I21: FALSE | J21: FALSE | K21: FALSE | L21: FALSE
D22: 10 | E22: Search Campaign | F22: FALSE | G22: FALSE | H22: FALSE | I22: FALSE | J22: FALSE | K22: FALSE | L22: FALSE
B23: =COUNTIF(F23:L24,TRUE)/COUNTA(F23:L24) -> 0 | C23: Champion | D23: 11 | E23: Build campaign setups via Excel or external tooling | F23: FALSE | G23: FALSE | H23: FALSE | I23: FALSE | J23: FALSE | K23: FALSE | L23: FALSE
D24: 12 | E24: Have a naming convention tool integration (grasp) | F24: FALSE | G24: FALSE | H24: FALSE | I24: FALSE | J24: FALSE | K24: FALSE | L24: FALSE
B25: 2
C26: Audiences & targeting | F26: =IFERROR(__xludf.DUMMYFUNCTION("SPARKLINE(COUNTIF(F28:L44,TRUE),{""charttype"",""bar"";""max"",COUNTA(F28:L44);""color1"",""green""})"),"") | N26: =COUNTIF(F28:L44,TRUE)/COUNTA(F28:L44) -> 0
B28: =COUNTIF(F28:L33,TRUE)/COUNTA(F28:L33) -> 0 | C28: Basic | D28: 1 | E28: Language targeting | F28: FALSE | G28: FALSE | H28: FALSE | I28: FALSE | J28: FALSE | K28: FALSE | L28: FALSE
D29: 2 | E29: Age targeting | F29: FALSE | G29: FALSE | H29: FALSE | I29: FALSE | J29: FALSE | K29: FALSE | L29: FALSE
D30: 3 | E30: Demographic targeting | F30: FALSE | G30: FALSE | H30: FALSE | I30: FALSE | J30: FALSE | K30: FALSE | L30: FALSE
D31: 4 | E31: Dedicated campaign per market | F31: FALSE | G31: FALSE | H31: FALSE | I31: FALSE | J31: FALSE | K31: FALSE | L31: FALSE
D32: 5 | E32: Is Video download/sharing allowed? | F32: FALSE | G32: FALSE | H32: FALSE | I32: FALSE | J32: FALSE | K32: FALSE | L32: FALSE
D33: 6 | E33: User Comments allowed | F33: FALSE | G33: FALSE | H33: FALSE | I33: FALSE | J33: FALSE | K33: FALSE | L33: FALSE
B34: =COUNTIF(F34:L39,TRUE)/COUNTA(F34:L39) -> 0 | C34: Advanced | D34: 7 | E34: Is there an audience framework in place (and used for targeting?) | F34: FALSE | G34: FALSE | H34: FALSE | I34: FALSE | J34: FALSE | K34: FALSE | L34: FALSE
D35: 8 | E35: Is there a persona in place from client side (the ideal customer) | F35: FALSE | G35: FALSE | H35: FALSE | I35: FALSE | J35: FALSE | K35: FALSE | L35: FALSE
D36: 9 | E36: Device targeting | F36: FALSE | G36: FALSE | H36: FALSE | I36: FALSE | J36: FALSE | K36: FALSE | L36: FALSE
D37: 10 | E37: Retargeting audiences | F37: FALSE | G37: FALSE | H37: FALSE | I37: FALSE | J37: FALSE | K37: FALSE | L37: FALSE
D38: 11 | E38: Specific placement targeting | F38: FALSE | G38: FALSE | H38: FALSE | I38: FALSE | J38: FALSE | K38: FALSE | L38: FALSE
D39: 12 | E39: Inplatform audiences (followers, retarget video viewers) | F39: FALSE | G39: FALSE | H39: FALSE | I39: FALSE | J39: FALSE | K39: FALSE | L39: FALSE
B40: =COUNTIF(F40:L42,TRUE)/COUNTA(F40:L42) -> 0 | C40: Expert | D40: 13 | E40: Event based audiences (on pixel events) | F40: FALSE | G40: FALSE | H40: FALSE | I40: FALSE | J40: FALSE | K40: FALSE | L40: FALSE
D41: 14 | E41: Bid control added | F41: FALSE | G41: FALSE | H41: FALSE | I41: FALSE | J41: FALSE | K41: FALSE | L41: FALSE
D42: 15 | E42: Customer List audiences | F42: FALSE | G42: FALSE | H42: FALSE | I42: FALSE | J42: FALSE | K42: FALSE | L42: FALSE
B43: =COUNTIF(F43:L44,TRUE)/COUNTA(F43:L44) -> 0 | C43: Champion | D43: 16 | E43: Customer Data Platform (CDP) integration | F43: FALSE | G43: FALSE | H43: FALSE | I43: FALSE | J43: FALSE | K43: FALSE | L43: FALSE
D44: 17 | E44: Comments Management | F44: FALSE | G44: FALSE | H44: FALSE | I44: FALSE | J44: FALSE | K44: FALSE | L44: FALSE
B45: 3
...

Sheet Snapchat
E2: MUST READ: How to use? 1. Only click a checkbox when the topic on the left - is 100% completed 2. Don't check the box if you "just" checked the topic if it was applicable 3. The same topic can be in multiple stages (different levels of maturity) | F2: FR | G2: NL | H2: DE | I2: BE | J2: UK | K2: US | L2: IT | M2: Adaptation topics (V) | N2: Topics not finalized (X) | P2: Last updated at 15/12/2025 by Laman Guliyeva
F3: TRUE | G3: TRUE | H3: TRUE | I3: TRUE | J3: TRUE | K3: TRUE | L3: TRUE | M3: =(COUNTIF(F:L,TRUE))-COUNTIF(F3:L3,true) -> 0 | N3: =COUNTIF(F:L,FALSE) -> 413
B4: =N111 -> 0 | F4: =COUNTIF(F:F,TRUE)-1 -> 0 | G4: =COUNTIF(G:G,TRUE)-1 -> 0 | H4: =COUNTIF(H:H,TRUE)-1 -> 0 | I4: =COUNTIF(I:I,TRUE)-1 -> 0 | J4: =COUNTIF(J:J,TRUE)-1 -> 0 | K4: =COUNTIF(K:K,TRUE)-1 -> 0 | L4: =COUNTIF(L:L,TRUE)-1 -> 0
F6: =COUNTIF(F:F,FALSE) -> 59 | G6: =COUNTIF(G:G,FALSE) -> 59 | H6: =COUNTIF(H:H,FALSE) -> 59 | I6: =COUNTIF(I:I,FALSE) -> 59 | J6: =COUNTIF(J:J,FALSE) -> 59 | K6: =COUNTIF(K:K,FALSE) -> 59 | L6: =COUNTIF(L:L,FALSE) -> 59
C8: Maturity | D8: # | E8: Topics | F8: FR | G8: NL | H8: DE | I8: BE | J8: UK | K8: US | L8: IT | M8: Details | N8: Comments / Action
E9: If a topic is not relevant for the client - delete the checkbox | F9: Only check a box if the topic is fully integrated | M9: Explain what the issue is if not checked | N9: What would be the next steps to finalize the topic
B10: 1
C11: Campaign setup | F11: =IFERROR(__xludf.DUMMYFUNCTION("SPARKLINE(COUNTIF(F13:L23,TRUE),{""charttype"",""bar"";""max"",COUNTA(F13:L23);""color1"",""green""})"),"") | N11: =COUNTIF(F13:L23,TRUE)/COUNTA(F13:L23) -> 0 | P11: Commentbox for feedback
B13: =COUNTIF(F13:L14,TRUE)/COUNTA(F13:L14) -> 0 | C13: Basic | D13: 1 | E13: Campaign setup based on algorithms | F13: FALSE | G13: FALSE | H13: FALSE | I13: FALSE | J13: FALSE | K13: FALSE | L13: FALSE
D14: 2 | E14: Organized structure | F14: FALSE | G14: FALSE | H14: FALSE | I14: FALSE | J14: FALSE | K14: FALSE | L14: FALSE
B15: =COUNTIF(F15:L20,TRUE)/COUNTA(F15:L20) -> 0 | C15: Advanced | D15: 3 | E15: Simple structure (easy to understand) | F15: FALSE | G15: FALSE | H15: FALSE | I15: FALSE | J15: FALSE | K15: FALSE | L15: FALSE
D16: 4 | E16: Naming convention on campaign level | F16: FALSE | G16: FALSE | H16: FALSE | I16: FALSE | J16: FALSE | K16: FALSE | L16: FALSE
D17: 5 | E17: Naming convention on ad group level | F17: FALSE | G17: FALSE | H17: FALSE | I17: FALSE | J17: FALSE | K17: FALSE | L17: FALSE
D18: 6 | E18: Naming convention on ad level | F18: FALSE | G18: FALSE | H18: FALSE | I18: FALSE | J18: FALSE | K18: FALSE | L18: FALSE
D19: 7 | E19: Structure in line with offer on the website | F19: FALSE | G19: FALSE | H19: FALSE | I19: FALSE | J19: FALSE | K19: FALSE | L19: FALSE
D20: 8 | E20: Attribution windows | F20: FALSE | G20: FALSE | H20: FALSE | I20: FALSE | J20: FALSE | K20: FALSE | L20: FALSE
B21: =COUNTIF(F21:L21,TRUE)/COUNTA(F21:L21) -> 0 | C21: Expert | D21: 9 | E21: Automatic Page View Campaign | F21: FALSE | G21: FALSE | H21: FALSE | I21: FALSE | J21: FALSE | K21: FALSE | L21: FALSE
B22: =COUNTIF(F22:L23,TRUE)/COUNTA(F22:L23) -> 0 | C22: Champion | D22: 10 | E22: Build campaign setups via Excel or external tooling | F22: FALSE | G22: FALSE | H22: FALSE | I22: FALSE | J22: FALSE | K22: FALSE | L22: FALSE
D23: 11 | E23: Have a naming convention tool integration (grasp) | F23: FALSE | G23: FALSE | H23: FALSE | I23: FALSE | J23: FALSE | K23: FALSE | L23: FALSE
B24: 2
C25: Audiences & targeting | F25: =IFERROR(__xludf.DUMMYFUNCTION("SPARKLINE(COUNTIF(F27:L41,TRUE),{""charttype"",""bar"";""max"",COUNTA(F27:L41);""color1"",""green""})"),"") | N25: =COUNTIF(F27:L41,TRUE)/COUNTA(F27:L41) -> 0
B27: =COUNTIF(F27:L30,TRUE)/COUNTA(F27:L30) -> 0 | C27: Basic | D27: 1 | E27: Language targeting | F27: FALSE | G27: FALSE | H27: FALSE | I27: FALSE | J27: FALSE | K27: FALSE | L27: FALSE
D28: 2 | E28: Age targeting | F28: FALSE | G28: FALSE | H28: FALSE | I28: FALSE | J28: FALSE | K28: FALSE | L28: FALSE
D29: 3 | E29: Demographic targeting | F29: FALSE | G29: FALSE | H29: FALSE | I29: FALSE | J29: FALSE | K29: FALSE | L29: FALSE
D30: 4 | E30: Dedicated campaign per market | F30: FALSE | G30: FALSE | H30: FALSE | I30: FALSE | J30: FALSE | K30: FALSE | L30: FALSE
B31: =COUNTIF(F31:L36,TRUE)/COUNTA(F31:L36) -> 0 | C31: Advanced | D31: 5 | E31: Is there an audience framework in place (and used for targeting?) | F31: FALSE | G31: FALSE | H31: FALSE | I31: FALSE | J31: FALSE | K31: FALSE | L31: FALSE
D32: 6 | E32: Is there a persona in place from client side (the ideal customer) | F32: FALSE | G32: FALSE | H32: FALSE | I32: FALSE | J32: FALSE | K32: FALSE | L32: FALSE
D33: 7 | E33: Device targeting | F33: FALSE | G33: FALSE | H33: FALSE | I33: FALSE | J33: FALSE | K33: FALSE | L33: FALSE
D34: 8 | E34: Retargeting audiences | F34: FALSE | G34: FALSE | H34: FALSE | I34: FALSE | J34: FALSE | K34: FALSE | L34: FALSE
D35: 9 | E35: Specific placement targeting | F35: FALSE | G35: FALSE | H35: FALSE | I35: FALSE | J35: FALSE | K35: FALSE | L35: FALSE
D36: 10 | E36: Inplatform audiences (followers, story viewers, retarget video viewers) | F36: FALSE | G36: FALSE | H36: FALSE | I36: FALSE | J36: FALSE | K36: FALSE | L36: FALSE
B37: =COUNTIF(F37:L40,TRUE)/COUNTA(F37:L40) -> 0 | C37: Expert | D37: 11 | E37: Event based audiences (on pixel events) | F37: FALSE | G37: FALSE | H37: FALSE | I37: FALSE | J37: FALSE | K37: FALSE | L37: FALSE
D38: 12 | E38: Smart Targeting On | F38: FALSE | G38: FALSE | H38: FALSE | I38: FALSE | J38: FALSE | K38: FALSE | L38: FALSE
D39: 13 | E39: Bid control added | F39: FALSE | G39: FALSE | H39: FALSE | I39: FALSE | J39: FALSE | K39: FALSE | L39: FALSE
D40: 14 | E40: Customer List audiences | F40: FALSE | G40: FALSE | H40: FALSE | I40: FALSE | J40: FALSE | K40: FALSE | L40: FALSE
B41: =COUNTIF(F41:L41,TRUE)/COUNTA(F41:L41) -> 0 | C41: Champion | D41: 15 | E41: Customer Data Platform (CDP) integration | F41: FALSE | G41: FALSE | H41: FALSE | I41: FALSE | J41: FALSE | K41: FALSE | L41: FALSE
B42: 3
C43: Conversion & KPI | F43: =IFERROR(__xludf.DUMMYFUNCTION("SPARKLINE(COUNTIF(F45:L51,TRUE),{""charttype"",""bar"";""max"",COUNTA(F45:L51);""color1"",""green""})"),"") | N43: =COUNTIF(F45:L51,TRUE)/COUNTA(F45:L51) -> 0
B45: =COUNTIF(F45:L46,TRUE)/COUNTA(F45:L46) -> 0 | C45: Basic | D45: 1 | E45: General goal for Snapchat (total) | F45: FALSE | G45: FALSE | H45: FALSE | I45: FALSE | J45: FALSE | K45: FALSE | L45: FALSE
D46: 2 | E46: Monthly performance check in on KPI's | F46: FALSE | G46: FALSE | H46: FALSE | I46: FALSE | J46: FALSE | K46: FALSE | L46: FALSE
...

Sheet SEO
E2: MUST READ: How to use? 1. Only click a checkbox when the topic on the left - is 100% completed 2. Don't check the box if you "just" checked the topic if it was applicable 3. The same topic can be in multiple stages (different levels of maturity) | F2: FR | G2: NL | H2: DE | I2: BE | J2: UK | K2: US | L2: IT | M2: Adaptation topics (V) | N2: Topics not finalized (X) | P2: Last updated at 22/09/2023 by Arlette Opzeeland
F3: TRUE | G3: TRUE | H3: TRUE | I3: TRUE | J3: TRUE | K3: TRUE | L3: TRUE | M3: =(COUNTIF(F:L,TRUE))-COUNTIF(F3:L3,true) -> 0 | N3: =COUNTIF(F:L,FALSE) -> 245
B4: =N88 -> 0 | F4: =COUNTIF(F:F,TRUE)-1 -> 0 | G4: =COUNTIF(G:G,TRUE)-1 -> 0 | H4: =COUNTIF(H:H,TRUE)-1 -> 0 | I4: =COUNTIF(I:I,TRUE)-1 -> 0 | J4: =COUNTIF(J:J,TRUE)-1 -> 0 | K4: =COUNTIF(K:K,TRUE)-1 -> 0 | L4: =COUNTIF(L:L,TRUE)-1 -> 0
F6: =COUNTIF(F:F,FALSE) -> 35 | G6: =COUNTIF(G:G,FALSE) -> 35 | H6: =COUNTIF(H:H,FALSE) -> 35 | I6: =COUNTIF(I:I,FALSE) -> 35 | J6: =COUNTIF(J:J,FALSE) -> 35 | K6: =COUNTIF(K:K,FALSE) -> 35 | L6: =COUNTIF(L:L,FALSE) -> 35
C8: Maturity | D8: # | E8: Topics | F8: FR | G8: NL | H8: DE | I8: BE | J8: UK | K8: US | L8: IT | M8: Details | N8: Next steps
E9: If a topic is not relevant for the client - delete the checkbox | F9: Only check a box if the topic is fully integrated | M9: Explain what the issue is if not checked | N9: What would be the next steps to finalize the topic
B10: 1
C11: Technical: Website configuration | F11: =IFERROR(__xludf.DUMMYFUNCTION("SPARKLINE(COUNTIF(F13:L20,TRUE),{""charttype"",""bar"";""max"",COUNTA(F13:L20);""color1"",""green""})"),"") | N11: =COUNTIF(F13:L20,TRUE)/COUNTA(F13:L20) -> 0 | P11: Commentbox for feedback
B13: =COUNTIF(F13:L15,TRUE)/COUNTA(F13:L15) -> 0 | C13: Basic | D13: 1 | E13: 404 page | F13: FALSE | G13: FALSE | H13: FALSE | I13: FALSE | J13: FALSE | K13: FALSE | L13: FALSE
D14: 2 | E14: HTTPS protocol | F14: FALSE | G14: FALSE | H14: FALSE | I14: FALSE | J14: FALSE | K14: FALSE | L14: FALSE
D15: 3 | E15: Robots.txt file | F15: FALSE | G15: FALSE | H15: FALSE | I15: FALSE | J15: FALSE | K15: FALSE | L15: FALSE
B16: =COUNTIF(F16:L19,TRUE)/COUNTA(F16:L19) -> 0 | C16: Advanced | D16: 4 | E16: Homepage accessible through multiple URLS | F16: FALSE | G16: FALSE | H16: FALSE | I16: FALSE | J16: FALSE | K16: FALSE | L16: FALSE
D17: 5 | E17: Server environment (Server errors) | F17: FALSE | G17: FALSE | H17: FALSE | I17: FALSE | J17: FALSE | K17: FALSE | L17: FALSE
D18: 6 | E18: XML sitemap | F18: FALSE | G18: FALSE | H18: FALSE | I18: FALSE | J18: FALSE | K18: FALSE | L18: FALSE
D19: 7 | E19: One URL per page | F19: FALSE | G19: FALSE | H19: FALSE | I19: FALSE | J19: FALSE | K19: FALSE | L19: FALSE
B20: =COUNTIF(F20:L20,TRUE)/COUNTA(F20:L20) -> 0 | C20: Expert | D20: 8 | E20: HTML validity | F20: FALSE | G20: FALSE | H20: FALSE | I20: FALSE | J20: FALSE | K20: FALSE | L20: FALSE
B21: 2
C22: Technical: Site structure | F22: =IFERROR(__xludf.DUMMYFUNCTION("SPARKLINE(COUNTIF(F24:L31,TRUE),{""charttype"",""bar"";""max"",COUNTA(F24:L31);""color1"",""green""})"),"") | N22: =COUNTIF(F24:L31,TRUE)/COUNTA(F24:L31) -> 0
B24: =COUNTIF(F24:L25,TRUE)/COUNTA(F24:L25) -> 0 | C24: Basic | D24: 1 | E24: URL structure | F24: FALSE | G24: FALSE | H24: FALSE | I24: FALSE | J24: FALSE | K24: FALSE | L24: FALSE
D25: 4 | E25: Homepage links | F25: FALSE | G25: FALSE | H25: FALSE | I25: FALSE | J25: FALSE | K25: FALSE | L25: FALSE
B26: =COUNTIF(F26:L28,TRUE)/COUNTA(F26:L28) -> 0 | C26: Advanced | D26: 5 | E26: Canonical annotation | F26: FALSE | G26: FALSE | H26: FALSE | I26: FALSE | J26: FALSE | K26: FALSE | L26: FALSE
D27: 3 | E27: Internal links | F27: FALSE | G27: FALSE | H27: FALSE | I27: FALSE | J27: FALSE | K27: FALSE | L27: FALSE
D28: 7 | E28: Pagination | F28: FALSE | G28: FALSE | H28: FALSE | I28: FALSE | J28: FALSE | K28: FALSE | L28: FALSE
B29: =COUNTIF(F29:L30,TRUE)/COUNTA(F29:L30) -> 0 | C29: Expert | D29: 6 | E29: URL parameters | F29: FALSE | G29: FALSE | H29: FALSE | I29: FALSE | J29: FALSE | K29: FALSE | L29: FALSE
D30: 8 | E30: Internationalisation | F30: FALSE | G30: FALSE | H30: FALSE | I30: FALSE | J30: FALSE | K30: FALSE | L30: FALSE
B31: =COUNTIF(F31:L31,TRUE)/COUNTA(F31:L31) -> 0 | C31: Champion | D31: 2 | E31: Visitibilty of relevant content | F31: FALSE | G31: FALSE | H31: FALSE | I31: FALSE | J31: FALSE | K31: FALSE | L31: FALSE
B32: 3
C33: Technical: Website content | F33: =IFERROR(__xludf.DUMMYFUNCTION("SPARKLINE(COUNTIF(F35:L42,TRUE),{""charttype"",""bar"";""max"",COUNTA(F35:L42);""color1"",""green""})"),"") | N33: =COUNTIF(F35:L42,TRUE)/COUNTA(F35:L42) -> 0
B35: =COUNTIF(F35:L38,TRUE)/COUNTA(F35:L38) -> 0 | C35: Basic | D35: 1 | E35: Page titles | F35: FALSE | G35: FALSE | H35: FALSE | I35: FALSE | J35: FALSE | K35: FALSE | L35: FALSE
D36: 2 | E36: Meta description | F36: FALSE | G36: FALSE | H36: FALSE | I36: FALSE | J36: FALSE | K36: FALSE | L36: FALSE
D37: 3 | E37: Heading tags | F37: FALSE | G37: FALSE | H37: FALSE | I37: FALSE | J37: FALSE | K37: FALSE | L37: FALSE
D38: 4 | E38: Images, links, and alt attributes | F38: FALSE | G38: FALSE | H38: FALSE | I38: FALSE | J38: FALSE | K38: FALSE | L38: FALSE
B39: =COUNTIF(F39:L41,TRUE)/COUNTA(F39:L41) -> 0 | C39: Advanced | D39: 5 | E39: Monitoring / dashboarding | F39: FALSE | G39: FALSE | H39: FALSE | I39: FALSE | J39: FALSE | K39: FALSE | L39: FALSE
D40: 6 | E40: Keyword research | F40: FALSE | G40: FALSE | H40: FALSE | I40: FALSE | J40: FALSE | K40: FALSE | L40: FALSE
D41: 7 | E41: Focus keywords | F41: FALSE | G41: FALSE | H41: FALSE | I41: FALSE | J41: FALSE | K41: FALSE | L41: FALSE
B42: =COUNTIF(F42:L42,TRUE)/COUNTA(F42:L42) -> 0 | C42: Champion | D42: 8 | E42: Structured data | F42: FALSE | G42: FALSE | H42: FALSE | I42: FALSE | J42: FALSE | K42: FALSE | L42: FALSE
B43: 4
C44: Authority | F44: =IFERROR(__xludf.DUMMYFUNCTION("SPARKLINE(COUNTIF(F46:L48,TRUE),{""charttype"",""bar"";""max"",COUNTA(F46:L48);""color1"",""green""})"),"") | N44: =COUNTIF(F46:F48,TRUE)/COUNTA(F46:L48) -> 0
B46: =COUNTIF(F46:L46,TRUE)/COUNTA(F46:L46) -> 0 | C46: Basic | D46: 1 | E46: Relevance and Authority of Referring Domains | F46: FALSE | G46: FALSE | H46: FALSE | I46: FALSE | J46: FALSE | K46: FALSE | L46: FALSE
B47: =COUNTIF(F47:L48,TRUE)/COUNTA(F47:L48) -> 0 | C47: Advanced | D47: 2 | E47: Anchor Text Distribution | F47: FALSE | G47: FALSE | H47: FALSE | I47: FALSE | J47: FALSE | K47: FALSE | L47: FALSE
...

Sheet CROUX
B2: CRO/UX | E2: MUST READ: How to use? 1. Only click a checkbox when the topic on the left - is 100% completed 2. Don't check the box if you "just" checked the topic if it was applicable 3. The same topic can be in multiple stages (different levels of maturity) | F2: FR | G2: NL | H2: DE | I2: BE | J2: UK | K2: US | L2: IT | M2: Adaptation topics (V) | N2: Topics not finalized (X) | R2: Last updated at 23/09/2025 by Delphine Holbecq
F3: TRUE | G3: TRUE | H3: TRUE | I3: TRUE | J3: TRUE | K3: TRUE | L3: TRUE | M3: =(COUNTIF(E:L,TRUE))-COUNTIF(E3:L3,true) -> 0 | N3: =COUNTIF(E:L,FALSE) -> 588
B4: =P163 -> 0 | F4: =COUNTIF(F13:F132,TRUE) -> 0 | G4: =COUNTIF(G13:G132,TRUE) -> 0 | H4: =COUNTIF(H13:H132,TRUE) -> 0 | I4: =COUNTIF(I13:I132,TRUE) -> 0 | J4: =COUNTIF(J13:J132,TRUE) -> 0 | K4: =COUNTIF(K13:K132,TRUE) -> 0 | L4: =COUNTIF(L13:L132,TRUE) -> 0
F6: =COUNTIF(F13:F132,FALSE) -> 84 | G6: =COUNTIF(G13:G132,FALSE) -> 84 | H6: =COUNTIF(H13:H132,FALSE) -> 84 | I6: =COUNTIF(I13:I132,FALSE) -> 84 | J6: =COUNTIF(J13:J132,FALSE) -> 84 | K6: =COUNTIF(K13:K132,FALSE) -> 84 | L6: =COUNTIF(L13:L132,FALSE) -> 84
C8: Maturity | D8: # | E8: Topics | F8: FR | G8: NL | H8: DE | I8: BE | J8: UK | K8: US | L8: IT | M8: SR (Severity Rating) | N8: ER (Easy to fix Rating) | O8: Priority | P8: Comments / Action
